Loading catalog...

STDERR:
Traceback (most recent call last):
  File "/tmp/ipykernel_11/1736651845.py", line 12, in <module>
    runpy.run_path(script_path, run_name="__main__")
  File "<frozen runpy>", line 291, in run_path
  File "<frozen runpy>", line 98, in _run_module_code
  File "<frozen runpy>", line 88, in _run_code
  File "/mnt/data/earthquake_portfolio/train_baseline.py", line 67, in <module>
    main()
  File "/mnt/data/earthquake_portfolio/train_baseline.py", line 18, in main
    df = load_catalog(DATA_PATH)
         ^^^^^^^^^^^^^^^^^^^^^^^
  File "/mnt/data/earthquake_portfolio/data_loader.py", line 12, in load_catalog
    sample = p.read_text(errors='replace').splitlines()
         ^^^^^^^^^^^^^^^^^^^^^^^^^^^^^^^^^^^^^^^^^^^^^^^
  File "/home/sandbox/.local/lib/python3.11/site-packages/pandas/util/_decorators.py", line 211, in wrapper
    return func(*args, **kwargs)
           ^^^^^^^^^^^^^^^^^^^^^
  File "/home/sandbox/.local/lib/python3.11/site-packages/pandas/util/_decorators.py", line 331, in wrapper
    return func(*args, **kwargs)
           ^^^^^^^^^^^^^^^^^^^^^
  File "/home/sandbox/.local/lib/python3.11/site-packages/pandas/io/parsers/readers.py", line 950, in read_csv
    return _read(filepath_or_buffer, kwds)
           ^^^^^^^^^^^^^^^^^^^^^^^^^^^^^^^
  File "/home/sandbox/.local/lib/python3.11/site-packages/pandas/io/parsers/readers.py", line 605, in _read
    parser = TextFileReader(filepath_or_buffer, **kwds)
             ^^^^^^^^^^^^^^^^^^^^^^^^^^^^^^^^^^^^^^^^^^
  File "/home/sandbox/.local/lib/python3.11/site-packages/pandas/io/parsers/readers.py", line 1442, in __init__
    self._engine = self._make_engine(f, self.engine)
                   ^^^^^^^^^^^^^^^^^^^^^^^^^^^^^^^^^
  File "/home/sandbox/.local/lib/python3.11/site-packages/pandas/io/parsers/readers.py", line 1753, in _make_engine
    return mapping[engine](f, **self.options)
           ^^^^^^^^^^^^^^^^^^^^^^^^^^^^^^^^^^
  File "/home/sandbox/.local/lib/python3.11/site-packages/pandas/io/parsers/c_parser_wrapper.py", line 156, in __init__
    self._validate_parse_dates_presence(self.names)  # type: ignore[has-type]
    ^^^^^^^^^^^^^^^^^^^^^^^^^^^^^^^^^^^^^^^^^^^^^^^
  File "/home/sandbox/.local/lib/python3.11/site-packages/pandas/io/parsers/base_parser.py", line 217, in _validate_parse_dates_presence
    raise ValueError(
ValueError: Missing column provided to 'parse_dates': 'ot, tgl'
